<?xml version="1.0" encoding="utf-8"?>
<robot name="Poppy_Torso">
	<link name="base">
		<inertial>
			<origin xyz="-9.74926801495556E-06 0.0245809270022031 -0.0126310576435619" rpy="0 0 0"></origin>
			<mass value="0.304441048219244"></mass>
			<inertia ixx="0.000444379589701896" ixy="1.65486746667917E-08" ixz="-3.86276516415689E-09" iyy="0.00048561348802354" iyz="2.15649474149961E-05" izz="0.000421911604661064"></inertia>
		</inertial>
		<visual>
			<origin xyz="0 0 0" rpy="0 0 0"></origin>
			<geometry>
				<mesh filename="package://Poppy_Torso/meshes/base_visual.STL"></mesh>
			</geometry>
			<material name="">
				<color rgba="0.9 0.9 0.9 1.0"></color>
			</material>
		</visual>
		<collision>
			<origin xyz="0 0 0" rpy="0 0 0"></origin>
			<geometry>
				<mesh filename="package://Poppy_Torso/meshes/base_respondable.STL"></mesh>
			</geometry>
		</collision>
	</link>
	<link name="spine">
		<inertial>
			<origin xyz="-2.40404181622888E-07 0.0288451670610555 -0.0100975116173431" rpy="0 0 0"></origin>
			<mass value="0.0926815111299683"></mass>
			<inertia ixx="3.84763921301561E-05" ixy="-1.20593718688982E-09" ixz="-2.38686853561089E-10" iyy="2.73205150040803E-05" iyz="1.47490193478348E-06" izz="3.26595229928866E-05"></inertia>
		</inertial>
		<visual>
			<origin xyz="0 0 0" rpy="0 0 0"></origin>
			<geometry>
				<mesh filename="package://Poppy_Torso/meshes/spine_visual.STL"></mesh>
			</geometry>
			<material name="">
				<color rgba="0.9 0.9 0.9 1.0"></color>
			</material>
		</visual>
		<collision>
			<origin xyz="0 0 0" rpy="0 0 0"></origin>
			<geometry>
				<mesh filename="package://Poppy_Torso/meshes/spine_respondable.STL"></mesh>
			</geometry>
		</collision>
	</link>
	<link name="bust_motors">
		<inertial>
			<origin xyz="3.50872352602193E-05 0.0105220286991919 -0.0174331454397802" rpy="0 0 0"></origin>
			<mass value="0.158876054417129"></mass>
			<inertia ixx="0.000100953682916" ixy="-3.89105329887544E-07" ixz="9.71750445341545E-08" iyy="8.94288407127088E-05" iyz="-1.31738248300944E-06" izz="4.2622597249744E-05"></inertia>
		</inertial>
		<visual>
			<origin xyz="0 0 0" rpy="0 0 0"></origin>
			<geometry>
				<mesh filename="package://Poppy_Torso/meshes/bust_visual.STL"></mesh>
			</geometry>
			<material name="">
				<color rgba="0.9 0.9 0.9 1.0"></color>
			</material>
		</visual>
		<collision>
			<origin xyz="0 0 0" rpy="0 0 0"></origin>
			<geometry>
				<mesh filename="package://Poppy_Torso/meshes/bust_respondable.STL"></mesh>
			</geometry>
		</collision>
	</link>
	<link name="chest">
		<inertial>
			<origin xyz="2.16502093708977E-06 0.051494834637487 -0.0105461658967885" rpy="0 0 0"></origin>
			<mass value="0.262924546647766"></mass>
			<inertia ixx="0.000154596138060618" ixy="2.37341792243603E-08" ixz="-2.3634491566554E-08" iyy="0.000750952678880381" iyz="1.53507486626421E-06" izz="0.000688551029698055"></inertia>
		</inertial>
		<visual>
			<origin xyz="0 0 0" rpy="0 0 0"></origin>
			<geometry>
				<mesh filename="package://Poppy_Torso/meshes/chest_visual.STL"></mesh>
			</geometry>
			<material name="">
				<color rgba="0.9 0.9 0.9 1.0"></color>
			</material>
		</visual>
		<collision>
			<origin xyz="0 0 0" rpy="0 0 0"></origin>
			<geometry>
				<mesh filename="package://Poppy_Torso/meshes/chest_respondable.STL"></mesh>
			</geometry>
		</collision>
	</link>
	<link name="neck">
		<inertial>
			<origin xyz="-0.00147486363079189 0.00928455262636607 2.89600753380741E-06" rpy="0 0 0"></origin>
			<mass value="0.00588496516988366"></mass>
			<inertia ixx="7.25596636570398E-07" ixy="-9.29944216419528E-08" ixz="2.01438227026043E-10" iyy="2.33535976458608E-06" iyz="1.55383710790991E-11" izz="2.57395421284165E-06"></inertia>
		</inertial>
		<visual>
			<origin xyz="0 0 0" rpy="0 0 0"></origin>
			<geometry>
				<mesh filename="package://Poppy_Torso/meshes/neck_visual.STL"></mesh>
			</geometry>
			<material name="">
				<color rgba="0.9 0.9 0.9 1.0"></color>
			</material>
		</visual>
		<collision>
			<origin xyz="0 0 0" rpy="0 0 0"></origin>
			<geometry>
				<mesh filename="package://Poppy_Torso/meshes/neck_respondable.STL"></mesh>
			</geometry>
		</collision>
	</link>
	<link name="head">
		<inertial>
			<origin xyz="0.000557192931260033 0.0327428210753856 -0.0132526703496143" rpy="0 0 0"></origin>
			<mass value="0.188564677402165"></mass>
			<inertia ixx="0.000353349276053432" ixy="-2.18551305410159E-07" ixz="4.10859195006433E-06" iyy="0.000384594393505883" iyz="-2.16688817868271E-05" izz="0.000396655887789427"></inertia>
		</inertial>
		<visual>
			<origin xyz="0 0 0" rpy="0 0 0"></origin>
			<geometry>
				<mesh filename="package://Poppy_Torso/meshes/head_visual.STL"></mesh>
			</geometry>
			<material name="">
				<color rgba="0.9 0.9 0.9 1.0"></color>
			</material>
		</visual>
		<collision>
			<origin xyz="0 0 0" rpy="0 0 0"></origin>
			<geometry>
				<mesh filename="package://Poppy_Torso/meshes/head_respondable.STL"></mesh>
			</geometry>
		</collision>
	</link>
	<link name="r_shoulder">
		<inertial>
			<origin xyz="-0.0104831289118898 0.00172612373293796 -0.00916606535277945" rpy="0 0 0"></origin>
			<mass value="0.00848189595252892"></mass>
			<inertia ixx="3.40574053037303E-06" ixy="4.48539910128384E-08" ixz="-3.01050409281427E-08" iyy="3.57000945450025E-06" iyz="1.16024799669592E-08" izz="1.85571705062299E-06"></inertia>
		</inertial>
		<visual>
			<origin xyz="0 0 0" rpy="0 0 0"></origin>
			<geometry>
				<mesh filename="package://Poppy_Torso/meshes/r_shoulder_visual.STL"></mesh>
			</geometry>
			<material name="">
				<color rgba="0.9 0.9 0.9 1.0"></color>
			</material>
		</visual>
		<collision>
			<origin xyz="0 0 0" rpy="0 0 0"></origin>
			<geometry>
				<mesh filename="package://Poppy_Torso/meshes/r_shoulder_respondable.STL"></mesh>
			</geometry>
		</collision>
	</link>
	<link name="r_shoulder_motor">
		<inertial>
			<origin xyz="2.24524859149255E-07 -0.0125756770887728 -0.0085982551689308" rpy="0 0 0"></origin>
			<mass value="0.0828144642064673"></mass>
			<inertia ixx="2.76486436455355E-05" ixy="-1.31703554080169E-10" ixz="-6.69095857944708E-10" iyy="1.6442799920461E-05" iyz="7.2340141547735E-07" izz="2.26416495770308E-05"></inertia>
		</inertial>
		<visual>
			<origin xyz="0 0 0" rpy="0 0 0"></origin>
			<geometry>
				<mesh filename="package://Poppy_Torso/meshes/r_shoulder_motor_visual.STL"></mesh>
			</geometry>
			<material name="">
				<color rgba="0.9 0.9 0.9 1.0"></color>
			</material>
		</visual>
		<collision>
			<origin xyz="0 0 0" rpy="0 0 0"></origin>
			<geometry>
				<mesh filename="package://Poppy_Torso/meshes/r_shoulder_motor_respondable.STL"></mesh>
			</geometry>
		</collision>
	</link>
	<link name="r_upper_arm">
		<inertial>
			<origin xyz="-3.32548713521223E-05 0.0628256242258387 -0.0106376027333001" rpy="0 0 0"></origin>
			<mass value="0.16814085957724"></mass>
			<inertia ixx="0.000280827719414285" ixy="-6.03127767269455E-07" ixz="-3.86325402336742E-09" iyy="4.23293497956197E-05" iyz="3.11054354485249E-06" izz="0.00027591619563535"></inertia>
		</inertial>
		<visual>
			<origin xyz="0 0 0" rpy="0 0 0"></origin>
			<geometry>
				<mesh filename="package://meshes/r_upper_arm_visual.STL"></mesh>
			</geometry>
			<material name="">
				<color rgba="0.9 0.9 0.9 1.0"></color>
			</material>
		</visual>
		<collision>
			<origin xyz="0 0 0" rpy="0 0 0"></origin>
			<geometry>
				<mesh filename="package://meshes/r_upper_arm_respondable.STL"></mesh>
			</geometry>
		</collision>
	</link>
	<link name="r_forearm">
		<inertial>
			<origin xyz="-0.00691609004843832 -0.107157207279582 -0.00498971449145198" rpy="0 0 0"></origin>
			<mass value="0.0486519712384455"></mass>
			<inertia ixx="0.000185810284946174" ixy="7.32306439524687E-06" ixz="-9.09571193441087E-08" iyy="1.51060987356639E-05" iyz="-1.35871780134915E-05" izz="0.00018275371059442"></inertia>
		</inertial>
		<visual>
			<origin xyz="0 0 0" rpy="0 0 0"></origin>
			<geometry>
				<mesh filename="package://Poppy_Torso/meshes/r_forearm_visual.STL"></mesh>
			</geometry>
			<material name="">
				<color rgba="0.9 0.9 0.9 1.0"></color>
			</material>
		</visual>
		<collision>
			<origin xyz="0 0 0" rpy="0 0 0"></origin>
			<geometry>
				<mesh filename="package://Poppy_Torso/meshes/r_forearm_respondable.STL"></mesh>
			</geometry>
		</collision>
	</link>
	<link name="l_shoulder">
		<inertial>
			<origin xyz="0.0105107550364721 0.00179804682433171 -0.00915203083390112" rpy="0 0 0"></origin>
			<mass value="0.00843598833388653"></mass>
			<inertia ixx="3.39606842476909E-06" ixy="-4.79548412692014E-08" ixz="2.95433304950035E-08" iyy="3.56726040974559E-06" iyz="1.00379140238948E-08" izz="1.84634802704217E-06"></inertia>
		</inertial>
		<visual>
			<origin xyz="0 0 0" rpy="0 0 0"></origin>
			<geometry>
				<mesh filename="package://Poppy_Torso/meshes/l_shoulder_visual.STL"></mesh>
			</geometry>
			<material name="">
				<color rgba="0.9 0.9 0.9 1.0"></color>
			</material>
		</visual>
		<collision>
			<origin xyz="0 0 0" rpy="0 0 0"></origin>
			<geometry>
				<mesh filename="package://Poppy_Torso/meshes/l_shoulder_respondable.STL"></mesh>
			</geometry>
		</collision>
	</link>
	<link name="l_shoulder_motor">
		<inertial>
			<origin xyz="2.25557890282113E-07 -0.0125756747635647 -0.00859825840421122" rpy="0 0 0"></origin>
			<mass value="0.082814411658021"></mass>
			<inertia ixx="2.7648623312469E-05" ixy="-1.32234083145181E-10" ixz="-6.69084913308621E-10" iyy="1.64427861876741E-05" iyz="7.23399382479451E-07" izz="2.26416366114375E-05"></inertia>
		</inertial>
		<visual>
			<origin xyz="0 0 0" rpy="0 0 0"></origin>
			<geometry>
				<mesh filename="package://Poppy_Torso/meshes/l_shoulder_motor_visual.STL"></mesh>
			</geometry>
			<material name="">
				<color rgba="0.9 0.9 0.9 1.0"></color>
			</material>
		</visual>
		<collision>
			<origin xyz="0 0 0" rpy="0 0 0"></origin>
			<geometry>
				<mesh filename="package://Poppy_Torso/meshes/l_shoulder_motor_respondable.STL"></mesh>
			</geometry>
		</collision>
	</link>
	<link name="l_upper_arm">
		<inertial>
			<origin xyz="3.30518731642866E-05 0.0628256242231928 -0.0106376043749558" rpy="0 0 0"></origin>
			<mass value="0.168140859572398"></mass>
			<inertia ixx="0.000280827719319256" ixy="6.03218629893559E-07" ixz="3.24530722833658E-09" iyy="4.23293519917111E-05" iyz="3.11052764904881E-06" izz="0.000275916197869213"></inertia>
		</inertial>
		<visual>
			<origin xyz="0 0 0" rpy="0 0 0"></origin>
			<geometry>
				<mesh filename="package://meshes/l_upper_arm_visual.STL"></mesh>
			</geometry>
			<material name="">
				<color rgba="0.9 0.9 0.9 1.0"></color>
			</material>
		</visual>
		<collision>
			<origin xyz="0 0 0" rpy="0 0 0"></origin>
			<geometry>
				<mesh filename="package://meshes/l_upper_arm_respondable.STL"></mesh>
			</geometry>
		</collision>
	</link>
	<link name="l_forearm">
		<inertial>
			<origin xyz="0.00691508667512003 -0.107157301013597 -0.00499027850392402" rpy="0 0 0"></origin>
			<mass value="0.0486517775557926"></mass>
			<inertia ixx="0.000185803987345629" ixy="-7.31676533662061E-06" ixz="8.9803476607652E-08" iyy="1.51052658275603E-05" iyz="-1.35881066977447E-05" izz="0.000182746088047765"></inertia>
		</inertial>
		<visual>
			<origin xyz="0 0 0" rpy="0 0 0"></origin>
			<geometry>
				<mesh filename="package://Poppy_Torso/meshes/l_forearm_visual.STL"></mesh>
			</geometry>
			<material name="">
				<color rgba="0.9 0.9 0.9 1.0"></color>
			</material>
		</visual>
		<collision>
			<origin xyz="0 0 0" rpy="0 0 0"></origin>
			<geometry>
				<mesh filename="package://Poppy_Torso/meshes/l_forearm_respondable.STL"></mesh>
			</geometry>
		</collision>
	</link>
	<joint name="abs_z" type="revolute">
		<origin xyz="0 0 0.08965" rpy="1.5708 1.1258E-18 0.018388"></origin>
		<parent link="base"></parent>
		<child link="spine"></child>
		<axis xyz="0 1 0"></axis>
		<limit lower="-1.3962634016" upper="1.3962634016" effort="3.1" velocity="7.0"></limit>
	</joint>
	<joint name="bust_y" type="revolute">
		<origin xyz="0 0.07985 0.00279999999999998" rpy="0 0 0"></origin>
		<parent link="spine"></parent>
		<child link="bust_motors"></child>
		<axis xyz="-1 0 0"></axis>
		<limit effort="3.1" lower="-0.802851455917" upper="0.401425727959" velocity="7.0"></limit>
	</joint>
	<joint name="bust_x" type="revolute">
		<origin xyz="0 0 0" rpy="0 0 0"></origin>
		<parent link="bust_motors"></parent>
		<child link="chest"></child>
		<axis xyz="0 0 1"></axis>
		<limit effort="3.1" lower="-0.698131700798" upper="0.698131700798" velocity="7.0"></limit>
	</joint>
	<joint name="head_z" type="revolute">
		<origin xyz="0 0.084 0.00499999999999996" rpy="0 0 0"></origin>
		<parent link="chest"></parent>
		<child link="neck"></child>
		<axis xyz="0 1 0"></axis>
		<limit effort="1.8" lower="-1.74532925199" upper="1.74532925199" velocity="10.0"></limit>
	</joint>
	<joint name="head_y" type="revolute">
		<origin xyz="0 0.0199999999999999 0" rpy="-0.349065850398866 0 0"></origin>
		<parent link="neck"></parent>
		<child link="head"></child>
		<axis xyz="-1 0 0"></axis>
		<limit effort="1.8" lower="-0.698131700798" upper="0.13962634016" velocity="10.0"></limit>
	</joint>
	<joint name="l_shoulder_y" type="revolute">
		<origin xyz="0.0771000000000001 0.0499999999999999 0.00399999999999997" rpy="-1.5707963267949 0 0"></origin>
		<parent link="chest"></parent>
		<child link="l_shoulder"></child>
		<axis xyz="1 0 0"></axis>
		<limit effort="3.1" lower="-2.09439510239" upper="2.70526034059" velocity="7.0"></limit>
	</joint>
	<joint name="l_shoulder_x" type="revolute">
		<origin xyz="0.0284 0 0" rpy="3.14159265358979 0 1.5707963267949"></origin>
		<parent link="l_shoulder"></parent>
		<child link="l_shoulder_motor"></child>
		<axis xyz="0 0 1"></axis>
		<limit effort="3.1" lower="-1.83259571459" upper="1.91986217719" velocity="7.0"></limit>
	</joint>
	<joint name="l_arm_z" type="revolute">
		<origin xyz="0 0.03625 0.0185000000000001" rpy="0 0 0"></origin>
		<parent link="l_shoulder_motor"></parent>
		<child link="l_upper_arm"></child>
		<axis xyz="0 1 0"></axis>
		<limit effort="3.1" lower="-1.57079632679" upper="1.57079632679" velocity="7.0"></limit>
	</joint>
	<joint name="l_elbow_y" type="revolute">
		<origin xyz="0 0.11175 -0.00999999999999998" rpy="0 0 0"></origin>
		<parent link="l_upper_arm"></parent>
		<child link="l_forearm"></child>
		<axis xyz="1 0 0"></axis>
		<limit effort="3.1" lower="-2.44346095279" upper="0.0" velocity="7.0"></limit>
	</joint>
	<joint name="r_shoulder_y" type="revolute">
		<origin xyz="-0.0770999999999999 0.0500000000000002 0.00400000000000003" rpy="-1.5707963267949 0 0"></origin>
		<parent link="chest"></parent>
		<child link="r_shoulder"></child>
		<axis xyz="-1 0 0"></axis>
		<limit effort="3.1" lower="-2.70526034059" upper="2.09439510239" velocity="7.0"></limit>
	</joint>
	<joint name="r_shoulder_x" type="revolute">
		<origin xyz="-0.0284 0 0" rpy="3.14159265358979 0 -1.5707963267949"></origin>
		<parent link="r_shoulder"></parent>
		<child link="r_shoulder_motor"></child>
		<axis xyz="0 0 -1"></axis>
		<limit effort="3.1" lower="-1.91986217719" upper="1.83259571459" velocity="7.0"></limit>
	</joint>
	<joint name="r_arm_z" type="revolute">
		<origin xyz="0 0.03625 0.0185000000000002" rpy="0 0 0"></origin>
		<parent link="r_shoulder_motor"></parent>
		<child link="r_upper_arm"></child>
		<axis xyz="0 1 0"></axis>
		<limit effort="3.1" lower="-1.57079632679" upper="1.57079632679" velocity="7.0"></limit>
	</joint>
	<joint name="r_elbow_y" type="revolute">
		<origin xyz="0 0.11175 -0.01" rpy="0 0 0"></origin>
		<parent link="r_upper_arm"></parent>
		<child link="r_forearm"></child>
		<axis xyz="-1 0 0"></axis>
		<limit effort="3.1" lower="0.0" upper="2.56563400043" velocity="7.0"></limit>
	</joint>
</robot>
